<mujoco model="wriggly">
  <compiler angle="radian" autolimits="true"/>
  <default>
      <position forcelimited="true" forcerange="-3 3"/>
  </default>
  <asset>
    <mesh name="base_link" file="base_link.STL"/>
    <mesh name="Green Leg Holder" file="Green Leg Holder.STL"/>
    <mesh name="Central Link" file="Central Link.STL"/>
    <mesh name="Red Leg Central Link" file="Red Leg Central Link.STL"/>
    <mesh name="Red Leg Holder" file="Red Leg Holder.STL"/>
    <mesh name="Red Leg" file="Red Leg.STL"/>
    <texture type="skybox" builtin="gradient" rgb1="0.3 0.5 0.7" rgb2="0 0 0" width="512"
        height="3072"/>
    <texture type="2d" name="groundplane" builtin="checker" mark="edge" rgb1="0.2 0.3 0.4"
        rgb2="0.1 0.2 0.3" markrgb="0.8 0.8 0.8" width="300" height="300"/>
    <material name="groundplane" texture="groundplane" texuniform="true" texrepeat="5 5"
        reflectance="0.2"/>
  </asset>
  <worldbody>
      <!--geom conaffinity="1" condim="3" name="floor" pos="0 0 -0.1" rgba="0.2 0.6 1 1" size="0 0 0.05" type="plane" friction="0.6"/-->
    <geom name="floor" condim= "3" friction="0.9" size="0 0 0.05" type="plane" material="groundplane"/>
    <light name="ceiling" pos="0 0 2" dir="0 0 -1" directional="true"/>
    <camera name="target_from_origin" pos="0 0 1.25" xyaxes="0 -1 0 1 0 0"/>
    <camera name="fixed_right" pos="2 -3 0.5" xyaxes="1 0 0 0 0.08 0.92" fovy="15" mode="fixed"/> 

    <body name="green_leg">
        <joint name="asdf" pos="0 0 0"  type="free" damping="0.1" armature="0.005" frictionloss="0.01"/>
        <geom type="mesh" rgba="0.792157 0.819608 0.933333 1" mesh="base_link"/>
        
        <body name="Green Leg Holder" pos="0.3235 -0.23065 0" quat="0.5 -0.5 0.5 -0.5" gravcomp="0">
          <inertial pos="0.0172732 -1.71313e-05 -0.0312874" quat="0.707094 0.00279184 0.00136492 0.707112" mass="0.101" diaginertia="1.71483e-05 1.52784e-05 1.18772e-05"/>
          <joint name="Green_Leg Final Joint" pos="0 0 0" axis="1 0 0" damping="0.1" armature="0.005" frictionloss="0.01"/>
          <geom type="mesh" rgba="0.792157 0.819608 0.933333 1" mesh="Green Leg Holder"/>
          
          <body name="Central Link" pos="0.017 0 -0.1045" quat="0.707107 0 0 0.707107" gravcomp="0">
            <inertial pos="9.37688e-10 -0.0119557 -0.00143737" quat="0.707745 0.706468 -1.73858e-06 1.74172e-06" mass="0.091" diaginertia="1.40798e-05 1.31645e-05 8.83029e-06"/>
            <joint name="Green Leg Central Joint" pos="0 0 0" axis="0 0 1" damping="0.1" armature="0.005" frictionloss="0.01"/>
            <geom type="mesh" rgba="0.792157 0.819608 0.933333 1" mesh="Central Link"/>
            
            <body name="Red Leg Central Link" pos="0 0 -0.04515" quat="0.5 0.5 0.5 0.5" gravcomp="0">
              <inertial pos="-0.000634684 -0.0270609 -0.000240499" quat="0.707212 0.704458 -0.0410108 -0.0436829" mass="0.113" diaginertia="2.05457e-05 1.98685e-05 1.50592e-05"/>
              <joint name="Red Leg Central Joint" pos="0 0 0" axis="0 0 1" damping="0.1" armature="0.005" frictionloss="0.01"/>
              <geom type="mesh" rgba="0.792157 0.819608 0.933333 1" mesh="Red Leg Central Link"/>
              
              <body name="Red Leg Holder" pos="0 -0.10485 0" quat="-0.5 0.5 0.5 0.5" gravcomp="0">
                <inertial pos="9.37688e-10 -0.0119557 -0.00143737" quat="0.707745 0.706468 -1.73858e-06 1.74172e-06" mass="0.091" diaginertia="1.40798e-05 1.31645e-05 8.83029e-06"/>
                <joint name="Red Knee" pos="0 0 0" axis="0 0 1" damping="0.1" armature="0.005" frictionloss="0.01"/>
                <geom type="mesh" rgba="0.792157 0.819608 0.933333 1" mesh="Red Leg Holder"/>
                
                <body name="Red Leg" pos="0 0 -0.045" quat="0.5 -0.5 0.5 -0.5" gravcomp="0">
                  <inertial pos="0.00101128 0.025027 -0.000247357" quat="0.705699 0.707278 -0.0298534 -0.0292677" mass="0.112" diaginertia="2.31293e-05 2.08201e-05 1.20376e-05"/>
                  <joint name="Red Leg Final Joint" pos="0 0 0" axis="0 0 1" damping="0.1" armature="0.005" frictionloss="0.01"/>
                  <geom type="mesh" rgba="0.792157 0.819608 0.933333 1" mesh="Red Leg"/>
                </body>
              </body>
            </body>
          </body>
        </body>
    </body>
  </worldbody>
  <!--contact>
      <exclude name="exclude_0_1" body1="green_leg" body2="Green Leg Holder"/>
      <exclude name="exclude_1_2" body1="Green Leg Holder" body2="Central Link"/>
      <exclude name="exclude_2_3" body1="Central Link" body2="Red Leg Central Link"/>
      <exclude name="exclude_3_4" body1="Red Leg Central Link" body2="Red Leg Holder"/>
      <exclude name="exclude_4_5" body1="Red Leg Holder" body2="Red Leg"/>
  </contact-->
  <actuator>
      <position name="act0" kp ="2" joint="Green_Leg Final Joint"   ctrlrange="-1.57 1.57"/>
      <position name="act1" kp ="2" joint="Green Leg Central Joint" ctrlrange="-3.14 3.14"/>
      <position name="act2" kp ="2" joint="Red Leg Central Joint"   ctrlrange="-1.57 1.57"/>
      <position name="act3" kp ="2" joint="Red Knee"                ctrlrange="-3.14 3.14"/>
      <position name="act4" kp ="2" joint="Red Leg Final Joint"     ctrlrange="-1.57 1.57"/>
  </actuator>
    <!--keyframe>
    <key
      name="flat"
      qpos="0 0 0.27 1 0 0 0 0 0.9 -1.8 0 0.9 -1.8 0 0.9 -1.8 0 0.9 -1.8"
      ctrl="0 0.9 -1.8 0 0.9 -1.8 0 0.9 -1.8 0 0.9 -1.8"/>
  </keyframe-->
</mujoco>