<mujoco model="wriggly">


  <compiler angle="radian" autolimits="true"/>


  <default>
      <position forcelimited="true" forcerange="-3 3"/>
  </default>


  <asset>
    <!-- Meshes -->
    <mesh name="base_link" file="../meshes/base_link.STL"/>
    <mesh name="green_leg_holder" file="../meshes/green_leg_holder.STL"/>
    <mesh name="central_link" file="../meshes/central_link.STL"/>
    <mesh name="red_central" file="../meshes/red_central.STL"/>
    <mesh name="red_leg_holder" file="../meshes/red_leg_holder.STL"/>
    <mesh name="red_leg" file="../meshes/red_leg.STL"/>
    <!-- Textures -->
    <texture type="skybox" builtin="gradient" rgb1="0.3 0.5 0.7" rgb2="0 0 0" width="512" height="3072"/>
    <texture type="2d" name="groundplane" builtin="checker" mark="edge" rgb1="0.2 0.3 0.4" rgb2="0.1 0.2 0.3" markrgb="0.8 0.8 0.8" width="300" height="300"/>
    <!-- Materials -->
    <material name="groundplane" texture="groundplane" texuniform="true" texrepeat="5 5" reflectance="0.2"/>
  </asset>


  <worldbody>
    <!-- Floor -->
    <geom name="floor" condim="3" friction="0.9" size="0 0 0.05" type="plane" material="groundplane"/>
    <!-- Light -->
    <light name="ceiling" pos="0 0 2" dir="0 0 -1" directional="true"/>
    <!-- Cameras -->
    <camera name="target_from_origin" pos="0 0 1.25" xyaxes="0 -1 0 1 0 0"/>
    <camera name="fixed_right" pos="2 -3 0.5" xyaxes="1 0 0 0 0.08 0.92" fovy="15" mode="fixed"/>

    <!-- Green Leg -->
    <body name="green_leg">
        <!-- Joint -->
        <joint name="asdf" pos="0 0 0" type="free" damping="0.1" armature="0.005" frictionloss="0.01"/>
        <!-- Base Link -->
        <geom type="mesh" rgba="0.792157 0.819608 0.933333 1" mesh="base_link"/>
        
        <!-- Green Leg Holder -->
        <body name="Green_Leg_Holder" pos="0.3235 -0.23065 0" quat="0.5 -0.5 0.5 -0.5" gravcomp="0">
          <inertial pos="0.0172732 -1.71313e-05 -0.0312874" quat="0.707094 0.00279184 0.00136492 0.707112" mass="0.101" diaginertia="1.71483e-05 1.52784e-05 1.18772e-05"/>
          <joint name="Green_Leg_Final_Joint" pos="0 0 0" axis="1 0 0" damping="0.1" armature="0.005" frictionloss="0.01"/>
          <geom type="mesh" rgba="0.792157 0.819608 0.933333 1" mesh="green_leg_holder"/>
          
          <!-- Central Link -->
          <body name="Central_Link" pos="0.017 0 -0.1045" quat="0.707107 0 0 0.707107" gravcomp="0">
            <inertial pos="9.37688e-10 -0.0119557 -0.00143737" quat="0.707745 0.706468 -1.73858e-06 1.74172e-06" mass="0.091" diaginertia="1.40798e-05 1.31645e-05 8.83029e-06"/>
            <joint name="Green_Leg_Central_Joint" pos="0 0 0" axis="0 0 1" damping="0.1" armature="0.005" frictionloss="0.01"/>
            <geom type="mesh" rgba="0.792157 0.819608 0.933333 1" mesh="central_link"/>
            
            <!-- Red Leg Central Link -->
            <body name="Red_Leg_Central_Link" pos="0 0 -0.04515" quat="0.5 0.5 0.5 0.5" gravcomp="0">
              <inertial pos="-0.000634684 -0.0270609 -0.000240499" quat="0.707212 0.704458 -0.0410108 -0.0436829" mass="0.113" diaginertia="2.05457e-05 1.98685e-05 1.50592e-05"/>
              <joint name="Red_Leg_Central_Joint" pos="0 0 0" axis="0 0 1" damping="0.1" armature="0.005" frictionloss="0.01"/>
              <geom type="mesh" rgba="0.792157 0.819608 0.933333 1" mesh="red_central"/>
              
              <!-- Red Leg Holder -->
              <body name="Red_Leg_Holder" pos="0 -0.10485 0" quat="-0.5 0.5 0.5 0.5" gravcomp="0">
                <inertial pos="9.37688e-10 -0.0119557 -0.00143737" quat="0.707745 0.706468 -1.73858e-06 1.74172e-06" mass="0.091" diaginertia="1.40798e-05 1.31645e-05 8.83029e-06"/>
                <joint name="Red_Knee" pos="0 0 0" axis="0 0 1" damping="0.1" armature="0.005" frictionloss="0.01"/>
                <geom type="mesh" rgba="0.792157 0.819608 0.933333 1" mesh="red_leg_holder"/>
                
                <!-- Red Leg -->
                <body name="Red_Leg" pos="0 0 -0.045" quat="0.5 -0.5 0.5 -0.5" gravcomp="0">
                  <inertial pos="0.00101128 0.025027 -0.000247357" quat="0.705699 0.707278 -0.0298534 -0.0292677" mass="0.112" diaginertia="2.31293e-05 2.08201e-05 1.20376e-05"/>
                  <joint name="Red_Leg_Final_Joint" pos="0 0 0" axis="0 0 1" damping="0.1" armature="0.005" frictionloss="0.01"/>
                  <geom type="mesh" rgba="0.792157 0.819608 0.933333 1" mesh="red_leg"/>
                </body>
              </body>
            </body>
          </body>
        </body>
    </body>
  </worldbody>


  <actuator>
      <position name="act0" kp ="2" joint="Green_Leg_Final_Joint"   ctrlrange="-1.57 1.57"/>
      <position name="act1" kp ="2" joint="Green_Leg_Central_Joint" ctrlrange="-3.14 3.14"/>
      <position name="act2" kp ="2" joint="Red_Leg_Central_Joint"   ctrlrange="-1.57 1.57"/>
      <position name="act3" kp ="2" joint="Red_Knee"                ctrlrange="-3.14 3.14"/>
      <position name="act4" kp ="2" joint="Red_Leg_Final_Joint"     ctrlrange="-1.57 1.57"/>
  </actuator>
</mujoco>