<mujoco>
  <worldbody>
    <!-- Green Leg -->
    <body name="green_leg" gravcomp="0">
        <!-- <inertial pos="0.364397154664965 -0.247649999434367 -6.01260156101907E-09" quat="0.5 -0.5 0.5 -0.5" mass="0.025" diaginertia="5.02495112065811E-06 7.84051273383468E-06 1.03414373246399E-05"/> -->
        <inertial pos="0.0 -0.0 0.0" quat="0.5 -0.5 0.5 -0.5" mass="0.025" diaginertia="5.02495112065811E-06 7.84051273383468E-06 1.03414373246399E-05"/>
        <joint name="free" pos="0 0 0" type="free"/>
        <geom name = "green_leg" pos = "-0.3235 0.23065 0" type="mesh" rgba="0.8 0.8 0.9 1" mesh="base_link"/>
        
        <!-- Green Leg Holder -->
        <!-- <body name="Green_Leg_Holder" pos="0.3235 -0.23065 0" quat="0.5 -0.5 0.5 -0.5" gravcomp="0"> -->
        <body name="Green_Leg_Holder" pos="0.0 -0.0 0" quat="0.5 -0.5 0.5 -0.5" gravcomp="0">
          <inertial pos="0.0172732 -1.71313e-05 -0.0312874" quat="0.707094 0.00279184 0.00136492 0.707112" mass="0.101" diaginertia="1.71483e-05 1.52784e-05 1.18772e-05"/>
          <joint name="Green_Leg_Final_Joint" pos="0 0 0" axis="1 0 0" damping="0.1" armature="0.005"/>
          <geom name = "Green_Leg_Holder" pos = "0. 0 0" type="mesh" rgba="0.8 0.8 0.9 1" mesh="green_leg_holder"/>
        </body>
    </body>
  </worldbody>
</mujoco>


<!--body>
  <inertial pos="0.364397154664965 -0.247649999434367 -6.01260156101907E-09" quat="1 0 0 0">
    <mass mass="0.0302629231778384"/>
    <inertia diaginertia="5.02495112065811E-06 7.84051273383468E-06 1.03414373246399E-05"/>
  </inertial>
  <geom type="plane" pos="0 0 0" quat="1 0 0 0"/>
</body-->
